Workbook

Sheet Assumptions
A1: ZARA & CO. — FP&A MODEL FY2025
A2: Assumptions Tab — All inputs live here. Never hardcode numbers in other tabs.
A3: Colour key: | B3: Blue = Hardcoded input | C3: Green = Formula | D3: (Black = formula in other tabs)
A5: A. MODEL PARAMETERS
A6: Fiscal Year | B6: 2025 | C6: Currency | D6: AED
A7: Company Name | B7: Zara & Co.
A9: B. OUTLETS & PRODUCT CATEGORIES
A10: Outlet 1 | B10: Dubai Mall | C10: Category 1 | D10: Women's Wear
A11: Outlet 2 | B11: Marina Mall | C11: Category 2 | D11: Men's Wear
A12: Outlet 3 | B12: Online | C12: Category 3 | D12: Kids' Wear
C13: Category 4 | D13: Accessories
A15: C. SEASONALITY MULTIPLIERS (1.00 = base month)
A16: Month | B16: Multiplier | C16: Note
A17: January | B17: 1.05 | C17: Post-holiday shopping
A18: February | B18: 1
A19: March | B19: 1.2 | C19: Ramadan — higher footfall & gifting
A20: April | B20: 0.9 | C20: Post-Ramadan dip
A21: May | B21: 1
A22: June | B22: 0.85 | C22: Summer begins
A23: July | B23: 0.8 | C23: Peak summer — expat travel
A24: August | B24: 0.85 | C24: Summer
A25: September | B25: 1.05 | C25: Back to school / work
A26: October | B26: 1.05
A27: November | B27: 1.1 | C27: White Friday / pre-holiday
A28: December | B28: 1.15 | C28: Holiday season + NYE
A29: Sum check (should ≈ 12) | B29: =SUM(B17:B28)
A31: D. BASE MONTHLY UNITS (per outlet, per category — before seasonality)
A32: Category | B32: Dubai Mall | C32: Marina Mall | D32: Online
A33: Women's Wear | B33: 800 | C33: 600 | D33: 1200
A34: Men's Wear | B34: 500 | C34: 380 | D34: 700
A35: Kids' Wear | B35: 300 | C35: 250 | D35: 500
A36: Accessories | B36: 600 | C36: 450 | D36: 900
A38: E. AVERAGE SELLING PRICE (AED)
A39: Category | B39: ASP (AED) | C39: Note
A40: Women's Wear | B40: 380 | C40: Premium positioning — Dubai Mall mix weighted
A41: Men's Wear | B41: 300
A42: Kids' Wear | B42: 160
A43: Accessories | B43: 130 | C43: Impulse-buy category — lower ASP, high volume
A45: F. COGS % BY CATEGORY (Week 4 — fill in when building COGS tab)
A46: Category | B46: COGS %
...

Sheet Revenue Build
A1: ZARA & CO. — REVENUE BUILD FY2025
A2: Formulas only — all inputs linked from Assumptions tab. Nothing hardcoded here.
A4: Outlet / Category | B4: Metric | C4: Jan | D4: Feb | E4: Mar | F4: Apr | G4: May | H4: Jun | I4: Jul | J4: Aug | K4: Sep | L4: Oct | M4: Nov | N4: Dec | O4: TOTAL
A5: Seasonality | C5: {=INDEX(Assumptions!$B$17:$B$28,COLUMN()-2)} | D5: {=INDEX(Assumptions!$B$17:$B$28,COLUMN()-2)} | E5: {=INDEX(Assumptions!$B$17:$B$28,COLUMN()-2)} | F5: {=INDEX(Assumptions!$B$17:$B$28,COLUMN()-2)} | G5: {=INDEX(Assumptions!$B$17:$B$28,COLUMN()-2)} | H5: {=INDEX(Assumptions!$B$17:$B$28,COLUMN()-2)} | I5: {=INDEX(Assumptions!$B$17:$B$28,COLUMN()-2)} | J5: {=INDEX(Assumptions!$B$17:$B$28,COLUMN()-2)} | ... N5: {=INDEX(Assumptions!$B$17:$B$28,COLUMN()-2)} | O5: =SUM(C5:N5)
A6: Dubai Mall
A7: Women's Wear | B7: Units | C7: =Assumptions!$B$33*'Revenue Build'!C$5 | D7: =Assumptions!$B$33*'Revenue Build'!D5 | E7: =Assumptions!$B$33*'Revenue Build'!E5 | F7: =Assumptions!$B$33*'Revenue Build'!F5 | G7: =Assumptions!$B$33*'Revenue Build'!G5 | H7: =Assumptions!$B$33*'Revenue Build'!H5 | I7: =Assumptions!$B$33*'Revenue Build'!I5 | J7: =Assumptions!$B$33*'Revenue Build'!J5 | K7: =Assumptions!$B$33*'Revenue Build'!K5 | ... N7: =Assumptions!$B$33*'Revenue Build'!N5 | O7: =SUM(C7:N7)
B8: Revenue (AED) | C8: =Assumptions!$B$40*'Revenue Build'!C7 | D8: =Assumptions!$B$40*'Revenue Build'!D7 | E8: =Assumptions!$B$40*'Revenue Build'!E7 | F8: =Assumptions!$B$40*'Revenue Build'!F7 | G8: =Assumptions!$B$40*'Revenue Build'!G7 | H8: =Assumptions!$B$40*'Revenue Build'!H7 | I8: =Assumptions!$B$40*'Revenue Build'!I7 | J8: =Assumptions!$B$40*'Revenue Build'!J7 | ... N8: =Assumptions!$B$40*'Revenue Build'!N7 | O8: =SUM(C8:N8)
A9: Men's Wear | B9: Units | C9: =Assumptions!$B$34*'Revenue Build'!C$5 | D9: =Assumptions!$B$34*'Revenue Build'!D$5 | E9: =Assumptions!$B$34*'Revenue Build'!E$5 | F9: =Assumptions!$B$34*'Revenue Build'!F$5 | G9: =Assumptions!$B$34*'Revenue Build'!G$5 | H9: =Assumptions!$B$34*'Revenue Build'!H$5 | I9: =Assumptions!$B$34*'Revenue Build'!I$5 | J9: =Assumptions!$B$34*'Revenue Build'!J$5 | ... N9: =Assumptions!$B$34*'Revenue Build'!N$5 | O9: =SUM(C9:N9)
B10: Revenue (AED) | C10: =C9*Assumptions!$B$41 | D10: =D9*Assumptions!$B$41 | E10: =E9*Assumptions!$B$41 | F10: =F9*Assumptions!$B$41 | G10: =G9*Assumptions!$B$41 | H10: =H9*Assumptions!$B$41 | I10: =I9*Assumptions!$B$41 | J10: =J9*Assumptions!$B$41 | ... N10: =N9*Assumptions!$B$41 | O10: =SUM(C10:N10)
A11: Kids' Wear | B11: Units | C11: =Assumptions!$B$35*'Revenue Build'!C$5 | D11: =Assumptions!$B$35*'Revenue Build'!D$5 | E11: =Assumptions!$B$35*'Revenue Build'!E$5 | F11: =Assumptions!$B$35*'Revenue Build'!F$5 | G11: =Assumptions!$B$35*'Revenue Build'!G$5 | H11: =Assumptions!$B$35*'Revenue Build'!H$5 | I11: =Assumptions!$B$35*'Revenue Build'!I$5 | J11: =Assumptions!$B$35*'Revenue Build'!J$5 | ... N11: =Assumptions!$B$35*'Revenue Build'!N$5 | O11: =SUM(C11:N11)
B12: Revenue (AED) | C12: =C11*Assumptions!$B$42 | D12: =D11*Assumptions!$B$42 | E12: =E11*Assumptions!$B$42 | F12: =F11*Assumptions!$B$42 | G12: =G11*Assumptions!$B$42 | H12: =H11*Assumptions!$B$42 | I12: =I11*Assumptions!$B$42 | J12: =J11*Assumptions!$B$42 | ... N12: =N11*Assumptions!$B$42 | O12: =SUM(C12:N12)
A13: Accessories | B13: Units | C13: =Assumptions!$B$36*'Revenue Build'!C$5 | D13: =Assumptions!$B$36*'Revenue Build'!D$5 | E13: =Assumptions!$B$36*'Revenue Build'!E$5 | F13: =Assumptions!$B$36*'Revenue Build'!F$5 | G13: =Assumptions!$B$36*'Revenue Build'!G$5 | H13: =Assumptions!$B$36*'Revenue Build'!H$5 | I13: =Assumptions!$B$36*'Revenue Build'!I$5 | J13: =Assumptions!$B$36*'Revenue Build'!J$5 | ... N13: =Assumptions!$B$36*'Revenue Build'!N$5 | O13: =SUM(C13:N13)
B14: Revenue (AED) | C14: =C13*Assumptions!$B$43 | D14: =D13*Assumptions!$B$43 | E14: =E13*Assumptions!$B$43 | F14: =F13*Assumptions!$B$43 | G14: =G13*Assumptions!$B$43 | H14: =H13*Assumptions!$B$43 | I14: =I13*Assumptions!$B$43 | J14: =J13*Assumptions!$B$43 | ... N14: =N13*Assumptions!$B$43 | O14: =SUM(C14:N14)
A15: Dubai Mall — Total Revenue | B15: AED | C15: =C8+C10+C12+C14 | D15: =D8+D10+D12+D14 | E15: =E8+E10+E12+E14 | F15: =F8+F10+F12+F14 | G15: =G8+G10+G12+G14 | H15: =H8+H10+H12+H14 | I15: =I8+I10+I12+I14 | J15: =J8+J10+J12+J14 | ... O15: =O8+O10+O12+O14
A17: Marina Mall
A18: Women's Wear | B18: Units | C18: =Assumptions!$C$33*'Revenue Build'!C$5 | D18: =Assumptions!$C$33*'Revenue Build'!D$5 | E18: =Assumptions!$C$33*'Revenue Build'!E$5 | F18: =Assumptions!$C$33*'Revenue Build'!F$5 | G18: =Assumptions!$C$33*'Revenue Build'!G$5 | H18: =Assumptions!$C$33*'Revenue Build'!H$5 | I18: =Assumptions!$C$33*'Revenue Build'!I$5 | J18: =Assumptions!$C$33*'Revenue Build'!J$5 | ... N18: =Assumptions!$C$33*'Revenue Build'!N$5 | O18: =SUM(C18:N18)
B19: Revenue (AED) | C19: =Assumptions!$B$40*'Revenue Build'!C18 | D19: =Assumptions!$B$40*'Revenue Build'!D18 | E19: =Assumptions!$B$40*'Revenue Build'!E18 | F19: =Assumptions!$B$40*'Revenue Build'!F18 | G19: =Assumptions!$B$40*'Revenue Build'!G18 | H19: =Assumptions!$B$40*'Revenue Build'!H18 | I19: =Assumptions!$B$40*'Revenue Build'!I18 | J19: =Assumptions!$B$40*'Revenue Build'!J18 | ... N19: =Assumptions!$B$40*'Revenue Build'!N18 | O19: =SUM(C19:N19)
A20: Men's Wear | B20: Units | C20: =Assumptions!$C$34*'Revenue Build'!C$5 | D20: =Assumptions!$C$34*'Revenue Build'!D$5 | E20: =Assumptions!$C$34*'Revenue Build'!E$5 | F20: =Assumptions!$C$34*'Revenue Build'!F$5 | G20: =Assumptions!$C$34*'Revenue Build'!G$5 | H20: =Assumptions!$C$34*'Revenue Build'!H$5 | I20: =Assumptions!$C$34*'Revenue Build'!I$5 | J20: =Assumptions!$C$34*'Revenue Build'!J$5 | ... N20: =Assumptions!$C$34*'Revenue Build'!N$5 | O20: =SUM(C20:N20)
B21: Revenue (AED) | C21: =C20*Assumptions!$B$41 | D21: =D20*Assumptions!$B$41 | E21: =E20*Assumptions!$B$41 | F21: =F20*Assumptions!$B$41 | G21: =G20*Assumptions!$B$41 | H21: =H20*Assumptions!$B$41 | I21: =I20*Assumptions!$B$41 | J21: =J20*Assumptions!$B$41 | ... N21: =N20*Assumptions!$B$41 | O21: =SUM(C21:N21)
A22: Kids' Wear | B22: Units | C22: =Assumptions!$C$35*'Revenue Build'!C$5 | D22: =Assumptions!$C$35*'Revenue Build'!D$5 | E22: =Assumptions!$C$35*'Revenue Build'!E$5 | F22: =Assumptions!$C$35*'Revenue Build'!F$5 | G22: =Assumptions!$C$35*'Revenue Build'!G$5 | H22: =Assumptions!$C$35*'Revenue Build'!H$5 | I22: =Assumptions!$C$35*'Revenue Build'!I$5 | J22: =Assumptions!$C$35*'Revenue Build'!J$5 | ... N22: =Assumptions!$C$35*'Revenue Build'!N$5 | O22: =SUM(C22:N22)
B23: Revenue (AED) | C23: =C22*Assumptions!$B$42 | D23: =D22*Assumptions!$B$42 | E23: =E22*Assumptions!$B$42 | F23: =F22*Assumptions!$B$42 | G23: =G22*Assumptions!$B$42 | H23: =H22*Assumptions!$B$42 | I23: =I22*Assumptions!$B$42 | J23: =J22*Assumptions!$B$42 | ... N23: =N22*Assumptions!$B$42 | O23: =SUM(C23:N23)
A24: Accessories | B24: Units | C24: =Assumptions!$C$36*'Revenue Build'!C$5 | D24: =Assumptions!$C$36*'Revenue Build'!D$5 | E24: =Assumptions!$C$36*'Revenue Build'!E$5 | F24: =Assumptions!$C$36*'Revenue Build'!F$5 | G24: =Assumptions!$C$36*'Revenue Build'!G$5 | H24: =Assumptions!$C$36*'Revenue Build'!H$5 | I24: =Assumptions!$C$36*'Revenue Build'!I$5 | J24: =Assumptions!$C$36*'Revenue Build'!J$5 | ... N24: =Assumptions!$C$36*'Revenue Build'!N$5 | O24: =SUM(C24:N24)
B25: Revenue (AED) | C25: =C24*Assumptions!$B$43 | D25: =D24*Assumptions!$B$43 | E25: =E24*Assumptions!$B$43 | F25: =F24*Assumptions!$B$43 | G25: =G24*Assumptions!$B$43 | H25: =H24*Assumptions!$B$43 | I25: =I24*Assumptions!$B$43 | J25: =J24*Assumptions!$B$43 | ... N25: =N24*Assumptions!$B$43 | O25: =SUM(C25:N25)
A26: Marina Mall — Total Revenue | B26: AED | C26: =C19+C21+C23+C25 | D26: =D19+D21+D23+D25 | E26: =E19+E21+E23+E25 | F26: =F19+F21+F23+F25 | G26: =G19+G21+G23+G25 | H26: =H19+H21+H23+H25 | I26: =I19+I21+I23+I25 | J26: =J19+J21+J23+J25 | ... O26: =O19+O21+O23+O25
A28: Online
A29: Women's Wear | B29: Units | C29: =Assumptions!$D$33*'Revenue Build'!C$5 | D29: =Assumptions!$D$33*'Revenue Build'!D$5 | E29: =Assumptions!$D$33*'Revenue Build'!E$5 | F29: =Assumptions!$D$33*'Revenue Build'!F$5 | G29: =Assumptions!$D$33*'Revenue Build'!G$5 | H29: =Assumptions!$D$33*'Revenue Build'!H$5 | I29: =Assumptions!$D$33*'Revenue Build'!I$5 | J29: =Assumptions!$D$33*'Revenue Build'!J$5 | ... N29: =Assumptions!$D$33*'Revenue Build'!N$5 | O29: =SUM(C29:N29)
B30: Revenue (AED) | C30: =Assumptions!$B$40*'Revenue Build'!C29 | D30: =Assumptions!$B$40*'Revenue Build'!D29 | E30: =Assumptions!$B$40*'Revenue Build'!E29 | F30: =Assumptions!$B$40*'Revenue Build'!F29 | G30: =Assumptions!$B$40*'Revenue Build'!G29 | H30: =Assumptions!$B$40*'Revenue Build'!H29 | I30: =Assumptions!$B$40*'Revenue Build'!I29 | J30: =Assumptions!$B$40*'Revenue Build'!J29 | ... N30: =Assumptions!$B$40*'Revenue Build'!N29 | O30: =SUM(C30:N30)
A31: Men's Wear | B31: Units | C31: =Assumptions!$D$34*'Revenue Build'!C$5 | D31: =Assumptions!$D$34*'Revenue Build'!D$5 | E31: =Assumptions!$D$34*'Revenue Build'!E$5 | F31: =Assumptions!$D$34*'Revenue Build'!F$5 | G31: =Assumptions!$D$34*'Revenue Build'!G$5 | H31: =Assumptions!$D$34*'Revenue Build'!H$5 | I31: =Assumptions!$D$34*'Revenue Build'!I$5 | J31: =Assumptions!$D$34*'Revenue Build'!J$5 | ... N31: =Assumptions!$D$34*'Revenue Build'!N$5 | O31: =SUM(C31:N31)
B32: Revenue (AED) | C32: =C31*Assumptions!$B$41 | D32: =D31*Assumptions!$B$41 | E32: =E31*Assumptions!$B$41 | F32: =F31*Assumptions!$B$41 | G32: =G31*Assumptions!$B$41 | H32: =H31*Assumptions!$B$41 | I32: =I31*Assumptions!$B$41 | J32: =J31*Assumptions!$B$41 | ... N32: =N31*Assumptions!$B$41 | O32: =SUM(C32:N32)
A33: Kids' Wear | B33: Units | C33: =Assumptions!$D$35*'Revenue Build'!C$5 | D33: =Assumptions!$D$35*'Revenue Build'!D$5 | E33: =Assumptions!$D$35*'Revenue Build'!E$5 | F33: =Assumptions!$D$35*'Revenue Build'!F$5 | G33: =Assumptions!$D$35*'Revenue Build'!G$5 | H33: =Assumptions!$D$35*'Revenue Build'!H$5 | I33: =Assumptions!$D$35*'Revenue Build'!I$5 | J33: =Assumptions!$D$35*'Revenue Build'!J$5 | ... N33: =Assumptions!$D$35*'Revenue Build'!N$5 | O33: =SUM(C33:N33)
B34: Revenue (AED) | C34: =C33*Assumptions!$B$42 | D34: =D33*Assumptions!$B$42 | E34: =E33*Assumptions!$B$42 | F34: =F33*Assumptions!$B$42 | G34: =G33*Assumptions!$B$42 | H34: =H33*Assumptions!$B$42 | I34: =I33*Assumptions!$B$42 | J34: =J33*Assumptions!$B$42 | ... N34: =N33*Assumptions!$B$42 | O34: =SUM(C34:N34)
A35: Accessories | B35: Units | C35: =Assumptions!$D$36*'Revenue Build'!C$5 | D35: =Assumptions!$D$36*'Revenue Build'!D$5 | E35: =Assumptions!$D$36*'Revenue Build'!E$5 | F35: =Assumptions!$D$36*'Revenue Build'!F$5 | G35: =Assumptions!$D$36*'Revenue Build'!G$5 | H35: =Assumptions!$D$36*'Revenue Build'!H$5 | I35: =Assumptions!$D$36*'Revenue Build'!I$5 | J35: =Assumptions!$D$36*'Revenue Build'!J$5 | ... N35: =Assumptions!$D$36*'Revenue Build'!N$5 | O35: =SUM(C35:N35)
B36: Revenue (AED) | C36: =C35*Assumptions!$B$43 | D36: =D35*Assumptions!$B$43 | E36: =E35*Assumptions!$B$43 | F36: =F35*Assumptions!$B$43 | G36: =G35*Assumptions!$B$43 | H36: =H35*Assumptions!$B$43 | I36: =I35*Assumptions!$B$43 | J36: =J35*Assumptions!$B$43 | ... N36: =N35*Assumptions!$B$43 | O36: =SUM(C36:N36)
A37: Online — Total Revenue | B37: AED | C37: =C30+C32+C34+C36 | D37: =D30+D32+D34+D36 | E37: =E30+E32+E34+E36 | F37: =F30+F32+F34+F36 | G37: =G30+G32+G34+G36 | H37: =H30+H32+H34+H36 | I37: =I30+I32+I34+I36 | J37: =J30+J32+J34+J36 | ... O37: =O30+O32+O34+O36
A39: TOTAL REVENUE — ALL OUTLETS | B39: AED | C39: =C15+C26+C37 | D39: =D15+D26+D37 | E39: =E15+E26+E37 | F39: =F15+F26+F37 | G39: =G15+G26+G37 | H39: =H15+H26+H37 | I39: =I15+I26+I37 | J39: =J15+J26+J37 | ... O39: =O15+O26+O37

Sheet COGS Build
A1: ZARA & CO. — COGS BUILD FY2025
A2: Formulas only — COGS% pulled from Assumptions, amounts = Revenue × COGS%.
A4: Outlet / Category | B4: COGS % | C4: Jan | D4: Feb | E4: Mar | F4: Apr | G4: May | H4: Jun | I4: Jul | J4: Aug | K4: Sep | L4: Oct | M4: Nov | N4: Dec | O4: TOTAL
A5: Dubai Mall
A6: Women's Wear | B6: =Assumptions!$B$47 | C6: ='Revenue Build'!C8*$B6 | D6: ='Revenue Build'!D8*$B6 | E6: ='Revenue Build'!E8*$B6 | F6: ='Revenue Build'!F8*$B6 | G6: ='Revenue Build'!G8*$B6 | H6: ='Revenue Build'!H8*$B6 | I6: ='Revenue Build'!I8*$B6 | J6: ='Revenue Build'!J8*$B6 | ... N6: ='Revenue Build'!N8*$B6 | O6: =SUM(C6:N6)
A7: Men's Wear | B7: =Assumptions!$B$48 | C7: ='Revenue Build'!C10*$B7 | D7: ='Revenue Build'!D10*$B7 | E7: ='Revenue Build'!E10*$B7 | F7: ='Revenue Build'!F10*$B7 | G7: ='Revenue Build'!G10*$B7 | H7: ='Revenue Build'!H10*$B7 | I7: ='Revenue Build'!I10*$B7 | J7: ='Revenue Build'!J10*$B7 | ... N7: ='Revenue Build'!N10*$B7 | O7: =SUM(C7:N7)
A8: Kids' Wear | B8: =Assumptions!$B$49 | C8: ='Revenue Build'!C12*$B8 | D8: ='Revenue Build'!D12*$B8 | E8: ='Revenue Build'!E12*$B8 | F8: ='Revenue Build'!F12*$B8 | G8: ='Revenue Build'!G12*$B8 | H8: ='Revenue Build'!H12*$B8 | I8: ='Revenue Build'!I12*$B8 | J8: ='Revenue Build'!J12*$B8 | ... N8: ='Revenue Build'!N12*$B8 | O8: =SUM(C8:N8)
A9: Accessories | B9: =Assumptions!$B$50 | C9: ='Revenue Build'!C14*$B9 | D9: ='Revenue Build'!D14*$B9 | E9: ='Revenue Build'!E14*$B9 | F9: ='Revenue Build'!F14*$B9 | G9: ='Revenue Build'!G14*$B9 | H9: ='Revenue Build'!H14*$B9 | I9: ='Revenue Build'!I14*$B9 | J9: ='Revenue Build'!J14*$B9 | ... N9: ='Revenue Build'!N14*$B9 | O9: =SUM(C9:N9)
A10: Dubai Mall — Total COGS | C10: =SUM(C6:C9) | D10: =SUM(D6:D9) | E10: =SUM(E6:E9) | F10: =SUM(F6:F9) | G10: =SUM(G6:G9) | H10: =SUM(H6:H9) | I10: =SUM(I6:I9) | J10: =SUM(J6:J9) | ... O10: =SUM(O6:O9)
A12: Marina Mall
A13: Women's Wear | B13: =Assumptions!$B$47 | C13: ='Revenue Build'!C19*$B13 | D13: ='Revenue Build'!D19*$B13 | E13: ='Revenue Build'!E19*$B13 | F13: ='Revenue Build'!F19*$B13 | G13: ='Revenue Build'!G19*$B13 | H13: ='Revenue Build'!H19*$B13 | I13: ='Revenue Build'!I19*$B13 | J13: ='Revenue Build'!J19*$B13 | ... N13: ='Revenue Build'!N19*$B13 | O13: =SUM(C13:N13)
A14: Men's Wear | B14: =Assumptions!$B$48 | C14: ='Revenue Build'!C21*$B14 | D14: ='Revenue Build'!D21*$B14 | E14: ='Revenue Build'!E21*$B14 | F14: ='Revenue Build'!F21*$B14 | G14: ='Revenue Build'!G21*$B14 | H14: ='Revenue Build'!H21*$B14 | I14: ='Revenue Build'!I21*$B14 | J14: ='Revenue Build'!J21*$B14 | ... N14: ='Revenue Build'!N21*$B14 | O14: =SUM(C14:N14)
A15: Kids' Wear | B15: =Assumptions!$B$49 | C15: ='Revenue Build'!C23*$B15 | D15: ='Revenue Build'!D23*$B15 | E15: ='Revenue Build'!E23*$B15 | F15: ='Revenue Build'!F23*$B15 | G15: ='Revenue Build'!G23*$B15 | H15: ='Revenue Build'!H23*$B15 | I15: ='Revenue Build'!I23*$B15 | J15: ='Revenue Build'!J23*$B15 | ... N15: ='Revenue Build'!N23*$B15 | O15: =SUM(C15:N15)
A16: Accessories | B16: =Assumptions!$B$50 | C16: ='Revenue Build'!C25*$B16 | D16: ='Revenue Build'!D25*$B16 | E16: ='Revenue Build'!E25*$B16 | F16: ='Revenue Build'!F25*$B16 | G16: ='Revenue Build'!G25*$B16 | H16: ='Revenue Build'!H25*$B16 | I16: ='Revenue Build'!I25*$B16 | J16: ='Revenue Build'!J25*$B16 | ... N16: ='Revenue Build'!N25*$B16 | O16: =SUM(C16:N16)
A17: Marina Mall — Total COGS | C17: =SUM(C13:C16) | D17: =SUM(D13:D16) | E17: =SUM(E13:E16) | F17: =SUM(F13:F16) | G17: =SUM(G13:G16) | H17: =SUM(H13:H16) | I17: =SUM(I13:I16) | J17: =SUM(J13:J16) | ... O17: =SUM(O13:O16)
A19: Online
A20: Women's Wear | B20: =Assumptions!$B$47 | C20: ='Revenue Build'!C30*$B20 | D20: ='Revenue Build'!D30*$B20 | E20: ='Revenue Build'!E30*$B20 | F20: ='Revenue Build'!F30*$B20 | G20: ='Revenue Build'!G30*$B20 | H20: ='Revenue Build'!H30*$B20 | I20: ='Revenue Build'!I30*$B20 | J20: ='Revenue Build'!J30*$B20 | ... N20: ='Revenue Build'!N30*$B20 | O20: =SUM(C20:N20)
A21: Men's Wear | B21: =Assumptions!$B$48 | C21: ='Revenue Build'!C32*$B21 | D21: ='Revenue Build'!D32*$B21 | E21: ='Revenue Build'!E32*$B21 | F21: ='Revenue Build'!F32*$B21 | G21: ='Revenue Build'!G32*$B21 | H21: ='Revenue Build'!H32*$B21 | I21: ='Revenue Build'!I32*$B21 | J21: ='Revenue Build'!J32*$B21 | ... N21: ='Revenue Build'!N32*$B21 | O21: =SUM(C21:N21)
A22: Kids' Wear | B22: =Assumptions!$B$49 | C22: ='Revenue Build'!C34*$B22 | D22: ='Revenue Build'!D34*$B22 | E22: ='Revenue Build'!E34*$B22 | F22: ='Revenue Build'!F34*$B22 | G22: ='Revenue Build'!G34*$B22 | H22: ='Revenue Build'!H34*$B22 | I22: ='Revenue Build'!I34*$B22 | J22: ='Revenue Build'!J34*$B22 | ... N22: ='Revenue Build'!N34*$B22 | O22: =SUM(C22:N22)
A23: Accessories | B23: =Assumptions!$B$50 | C23: ='Revenue Build'!C36*$B23 | D23: ='Revenue Build'!D36*$B23 | E23: ='Revenue Build'!E36*$B23 | F23: ='Revenue Build'!F36*$B23 | G23: ='Revenue Build'!G36*$B23 | H23: ='Revenue Build'!H36*$B23 | I23: ='Revenue Build'!I36*$B23 | J23: ='Revenue Build'!J36*$B23 | ... N23: ='Revenue Build'!N36*$B23 | O23: =SUM(C23:N23)
A24: Online — Total COGS | C24: =SUM(C20:C23) | D24: =SUM(D20:D23) | E24: =SUM(E20:E23) | F24: =SUM(F20:F23) | G24: =SUM(G20:G23) | H24: =SUM(H20:H23) | I24: =SUM(I20:I23) | J24: =SUM(J20:J23) | ... O24: =SUM(O20:O23)
A26: TOTAL COGS — ALL OUTLETS | C26: =C10+C17+C24 | D26: =D10+D17+D24 | E26: =E10+E17+E24 | F26: =F10+F17+F24 | G26: =G10+G17+G24 | H26: =H10+H17+H24 | I26: =I10+I17+I24 | J26: =J10+J17+J24 | ... O26: =O10+O17+O24

Sheet OpEx Detail
A1: ZARA & CO. — OPEX DETAIL FY2025
A2: Formulas only — fixed costs from Assumptions, marketing linked to Revenue Build.
A4: Item | C4: Jan | D4: Feb | E4: Mar | F4: Apr | G4: May | H4: Jun | I4: Jul | J4: Aug | K4: Sep | L4: Oct | M4: Nov | N4: Dec | O4: TOTAL
A5: Dubai Mall
A6: Rent | C6: =Assumptions!$B$54 | D6: =Assumptions!$B$54 | E6: =Assumptions!$B$54 | F6: =Assumptions!$B$54 | G6: =Assumptions!$B$54 | H6: =Assumptions!$B$54 | I6: =Assumptions!$B$54 | J6: =Assumptions!$B$54 | ... N6: =Assumptions!$B$54 | O6: =SUM(C6:N6)
A7: Payroll | C7: =Assumptions!$B$55 | D7: =Assumptions!$B$55 | E7: =Assumptions!$B$55 | F7: =Assumptions!$B$55 | G7: =Assumptions!$B$55 | H7: =Assumptions!$B$55 | I7: =Assumptions!$B$55 | J7: =Assumptions!$B$55 | ... N7: =Assumptions!$B$55 | O7: =SUM(C7:N7)
A8: Marketing | C8: ='Revenue Build'!C$15*Assumptions!$B$56 | D8: ='Revenue Build'!D$15*Assumptions!$B$56 | E8: ='Revenue Build'!E$15*Assumptions!$B$56 | F8: ='Revenue Build'!F$15*Assumptions!$B$56 | G8: ='Revenue Build'!G$15*Assumptions!$B$56 | H8: ='Revenue Build'!H$15*Assumptions!$B$56 | I8: ='Revenue Build'!I$15*Assumptions!$B$56 | J8: ='Revenue Build'!J$15*Assumptions!$B$56 | ... N8: ='Revenue Build'!N$15*Assumptions!$B$56 | O8: =SUM(C8:N8)
A9: Dubai Mall — Total OpEx | C9: =SUM(C6:C8) | D9: =SUM(D6:D8) | E9: =SUM(E6:E8) | F9: =SUM(F6:F8) | G9: =SUM(G6:G8) | H9: =SUM(H6:H8) | I9: =SUM(I6:I8) | J9: =SUM(J6:J8) | ... O9: =SUM(O6:O8)
A11: Marina Mall
A12: Rent | C12: =Assumptions!$C$54 | D12: =Assumptions!$C$54 | E12: =Assumptions!$C$54 | F12: =Assumptions!$C$54 | G12: =Assumptions!$C$54 | H12: =Assumptions!$C$54 | I12: =Assumptions!$C$54 | J12: =Assumptions!$C$54 | ... N12: =Assumptions!$C$54 | O12: =SUM(C12:N12)
A13: Payroll | C13: =Assumptions!$C$55 | D13: =Assumptions!$C$55 | E13: =Assumptions!$C$55 | F13: =Assumptions!$C$55 | G13: =Assumptions!$C$55 | H13: =Assumptions!$C$55 | I13: =Assumptions!$C$55 | J13: =Assumptions!$C$55 | ... N13: =Assumptions!$C$55 | O13: =SUM(C13:N13)
A14: Marketing | C14: ='Revenue Build'!C$26*Assumptions!$C$56 | D14: ='Revenue Build'!D$26*Assumptions!$C$56 | E14: ='Revenue Build'!E$26*Assumptions!$C$56 | F14: ='Revenue Build'!F$26*Assumptions!$C$56 | G14: ='Revenue Build'!G$26*Assumptions!$C$56 | H14: ='Revenue Build'!H$26*Assumptions!$C$56 | I14: ='Revenue Build'!I$26*Assumptions!$C$56 | J14: ='Revenue Build'!J$26*Assumptions!$C$56 | ... N14: ='Revenue Build'!N$26*Assumptions!$C$56 | O14: =SUM(C14:N14)
A15: Marina Mall — Total OpEx | C15: =SUM(C12:C14) | D15: =SUM(D12:D14) | E15: =SUM(E12:E14) | F15: =SUM(F12:F14) | G15: =SUM(G12:G14) | H15: =SUM(H12:H14) | I15: =SUM(I12:I14) | J15: =SUM(J12:J14) | ... O15: =SUM(O12:O14)
A17: Online
A18: Rent | C18: =Assumptions!$D$54 | D18: =Assumptions!$D$54 | E18: =Assumptions!$D$54 | F18: =Assumptions!$D$54 | G18: =Assumptions!$D$54 | H18: =Assumptions!$D$54 | I18: =Assumptions!$D$54 | J18: =Assumptions!$D$54 | ... N18: =Assumptions!$D$54 | O18: =SUM(C18:N18)
A19: Payroll | C19: =Assumptions!$D$55 | D19: =Assumptions!$D$55 | E19: =Assumptions!$D$55 | F19: =Assumptions!$D$55 | G19: =Assumptions!$D$55 | H19: =Assumptions!$D$55 | I19: =Assumptions!$D$55 | J19: =Assumptions!$D$55 | ... N19: =Assumptions!$D$55 | O19: =SUM(C19:N19)
A20: Marketing | C20: ='Revenue Build'!C$37*Assumptions!$D$56 | D20: ='Revenue Build'!D$37*Assumptions!$D$56 | E20: ='Revenue Build'!E$37*Assumptions!$D$56 | F20: ='Revenue Build'!F$37*Assumptions!$D$56 | G20: ='Revenue Build'!G$37*Assumptions!$D$56 | H20: ='Revenue Build'!H$37*Assumptions!$D$56 | I20: ='Revenue Build'!I$37*Assumptions!$D$56 | J20: ='Revenue Build'!J$37*Assumptions!$D$56 | ... N20: ='Revenue Build'!N$37*Assumptions!$D$56 | O20: =SUM(C20:N20)
A21: Online — Total OpEx | C21: =SUM(C18:C20) | D21: =SUM(D18:D20) | E21: =SUM(E18:E20) | F21: =SUM(F18:F20) | G21: =SUM(G18:G20) | H21: =SUM(H18:H20) | I21: =SUM(I18:I20) | J21: =SUM(J18:J20) | ... O21: =SUM(O18:O20)
A23: TOTAL OPEX — ALL OUTLETS | C23: =C9+C15+C21 | D23: =D9+D15+D21 | E23: =E9+E15+E21 | F23: =F9+F15+F21 | G23: =G9+G15+G21 | H23: =H9+H15+H21 | I23: =I9+I15+I21 | J23: =J9+J15+J21 | ... O23: =O9+O15+O21

Sheet P&L Summary
A1: ZARA & CO. — P&L SUMMARY FY2025
A2: Budget linked from Revenue Build / COGS Build / OpEx Detail. Actuals hardcoded.
A3: Colour key: | B3: FY2024 Prior Year | C3: Budget (formula) | D3: Actual (hardcoded)
A5: Line Item | B5: FY2024 Actual | C5: Jan Budget | D5: Feb Budget | E5: Mar Budget | F5: Apr Budget | G5: May Budget | H5: Jun Budget | I5: Jul Budget | J5: Aug Budget | K5: Sep Budget | L5: Oct Budget | M5: Nov Budget | N5: Dec Budget | O5: FY2025 Budget | P5: Jan Actual | Q5: Feb Actual | R5: Mar Actual
A6: Revenue | B6: 19800000 | C6: ='Revenue Build'!C39 | D6: ='Revenue Build'!D39 | E6: ='Revenue Build'!E39 | F6: ='Revenue Build'!F39 | G6: ='Revenue Build'!G39 | H6: ='Revenue Build'!H39 | I6: ='Revenue Build'!I39 | J6: ='Revenue Build'!J39 | ... O6: ='Revenue Build'!O39 | P6: 1900000 | Q6: 1860000 | R6: 2280000
A7: Less: COGS | B7: 9200000 | C7: ='COGS Build'!C26 | D7: ='COGS Build'!D26 | E7: ='COGS Build'!E26 | F7: ='COGS Build'!F26 | G7: ='COGS Build'!G26 | H7: ='COGS Build'!H26 | I7: ='COGS Build'!I26 | J7: ='COGS Build'!J26 | ... O7: ='COGS Build'!O26 | P7: 858000 | Q7: 840000 | R7: 1040000
A8: Gross Profit | B8: =B6-B7 | C8: =C6-C7 | D8: =D6-D7 | E8: =E6-E7 | F8: =F6-F7 | G8: =G6-G7 | H8: =H6-H7 | I8: =I6-I7 | ... R8: =R6-R7
A9: Gross Margin % | B9: =B8/B6 | C9: =C8/C6 | D9: =D8/D6 | E9: =E8/E6 | F9: =F8/F6 | G9: =G8/G6 | H9: =H8/H6 | I9: =I8/I6 | ... R9: =R8/R6
A11: Less: OpEx | B11: 7100000 | C11: ='OpEx Detail'!C23 | D11: ='OpEx Detail'!D23 | E11: ='OpEx Detail'!E23 | F11: ='OpEx Detail'!F23 | G11: ='OpEx Detail'!G23 | H11: ='OpEx Detail'!H23 | I11: ='OpEx Detail'!I23 | J11: ='OpEx Detail'!J23 | ... O11: ='OpEx Detail'!O23 | P11: 685000 | Q11: 658000 | R11: 710000
A12: Operating Profit | B12: =B8-B11 | C12: =C8-C11 | D12: =D8-D11 | E12: =E8-E11 | F12: =F8-F11 | G12: =G8-G11 | H12: =H8-H11 | I12: =I8-I11 | ... R12: =R8-R11
A13: Operating Margin % | B13: =B12/B6 | C13: =C12/C6 | D13: =D12/D6 | E13: =E12/E6 | F13: =F12/F6 | G13: =G12/G6 | H13: =H12/H6 | I13: =I12/I6 | ... R13: =R12/R6

Sheet Variance Analysis
A1: ZARA & CO. — VARIANCE ANALYSIS FY2025
A2: Actual vs Budget — Q1 YTD. $ Var = Actual − Budget. Fav/Unfav: revenue & profit lines Fav if positive; cost lines Fav if negative.
A3: Colour key: | B3: Budget | C3: Actual | D3: Fav (green) / Unfav (red) — conditional formatting applied by Ashnad
B5: January | H5: February | N5: March | T5: Q1 Total
B6: Budget | C6: Actual | D6: $ Variance | E6: Fav/Unfav | F6: % Variance | H6: Budget | I6: Actual | J6: $ Variance | K6: Fav/Unfav | L6: % Variance | N6: Budget | O6: Actual | P6: $ Variance | Q6: Fav/Unfav | R6: % Variance | T6: Budget | U6: Actual | V6: $ Variance | W6: Fav/Unfav | X6: % Variance
A7: Revenue | B7: ='P&L Summary'!C6 | C7: ='P&L Summary'!P6 | D7: =C7-B7 | E7: =IF(D7<0,"Unfav","Fav") | F7: =D7/B7 | H7: ='P&L Summary'!D6 | I7: ='P&L Summary'!Q6 | J7: =I7-H7 | K7: =IF(J7<0,"Unfav","Fav") | L7: =J7/H7 | N7: ='P&L Summary'!E6 | O7: ='P&L Summary'!R6 | P7: =O7-N7 | Q7: =IF(P7<0,"Unfav","Fav") | R7: =P7/N7 | T7: =B7+H7+N7 | U7: =C7+I7+O7 | V7: =D7+J7+P7 | W7: =IF(V7<0,"Unfav","Fav") | X7: =V7/T7
A8: Less: COGS | B8: ='P&L Summary'!C7 | C8: ='P&L Summary'!P7 | D8: =C8-B8 | E8: =IF(D8>0,"Unfav","Fav") | F8: =D8/B8 | H8: ='P&L Summary'!D7 | I8: ='P&L Summary'!Q7 | J8: =I8-H8 | K8: =IF(J8>0,"Unfav","Fav") | L8: =J8/H8 | N8: ='P&L Summary'!E7 | O8: ='P&L Summary'!R7 | P8: =O8-N8 | Q8: =IF(P8>0,"Unfav","Fav") | R8: =P8/N8 | T8: =B8+H8+N8 | U8: =C8+I8+O8 | V8: =D8+J8+P8 | W8: =IF(V8>0,"Unfav","Fav") | X8: =V8/T8
A9: Gross Profit | B9: ='P&L Summary'!C8 | C9: ='P&L Summary'!P8 | D9: =C9-B9 | E9: =IF(D9<0,"Unfav","Fav") | F9: =D9/B9 | H9: ='P&L Summary'!D8 | I9: ='P&L Summary'!Q8 | J9: =I9-H9 | K9: =IF(J9<0,"Unfav","Fav") | L9: =J9/H9 | N9: ='P&L Summary'!E8 | O9: ='P&L Summary'!R8 | P9: =O9-N9 | Q9: =IF(P9<0,"Unfav","Fav") | R9: =P9/N9 | T9: =B9+H9+N9 | U9: =C9+I9+O9 | V9: =D9+J9+P9 | W9: =IF(V9<0,"Unfav","Fav") | X9: =V9/T9
A10: Gross Margin % | B10: ='P&L Summary'!C9 | C10: ='P&L Summary'!P9 | D10: =C10-B10 | E10: =IF(D10<0,"Unfav","Fav") | H10: ='P&L Summary'!D9 | I10: ='P&L Summary'!Q9 | J10: =I10-H10 | K10: =IF(J10<0,"Unfav","Fav") | N10: ='P&L Summary'!E9 | O10: ='P&L Summary'!R9 | P10: =O10-N10 | Q10: =IF(P10<0,"Unfav","Fav") | T10: =T9/T7 | U10: =U9/U7 | V10: =U10-T10 | W10: =IF(V10<0,"Unfav","Fav")
A12: Less: OpEx | B12: ='P&L Summary'!C11 | C12: ='P&L Summary'!P11 | D12: =C12-B12 | E12: =IF(D12>0,"Unfav","Fav") | F12: =D12/B12 | H12: ='P&L Summary'!D11 | I12: ='P&L Summary'!Q11 | J12: =I12-H12 | K12: =IF(J12>0,"Unfav","Fav") | L12: =J12/H12 | N12: ='P&L Summary'!E11 | O12: ='P&L Summary'!R11 | P12: =O12-N12 | Q12: =IF(P12>0,"Unfav","Fav") | R12: =P12/N12 | T12: =B12+H12+N12 | U12: =C12+I12+O12 | V12: =D12+J12+P12 | W12: =IF(V12>0,"Unfav","Fav") | X12: =V12/T12
A13: Operating Profit | B13: ='P&L Summary'!C12 | C13: ='P&L Summary'!P12 | D13: =C13-B13 | E13: =IF(D13<0,"Unfav","Fav") | F13: =D13/B13 | H13: ='P&L Summary'!D12 | I13: ='P&L Summary'!Q12 | J13: =I13-H13 | K13: =IF(J13<0,"Unfav","Fav") | L13: =J13/H13 | N13: ='P&L Summary'!E12 | O13: ='P&L Summary'!R12 | P13: =O13-N13 | Q13: =IF(P13<0,"Unfav","Fav") | R13: =P13/N13 | T13: =B13+H13+N13 | U13: =C13+I13+O13 | V13: =D13+J13+P13 | W13: =IF(V13<0,"Unfav","Fav") | X13: =V13/T13
A14: Operating Margin % | B14: ='P&L Summary'!C13 | C14: ='P&L Summary'!P13 | D14: =C14-B14 | E14: =IF(D14<0,"Unfav","Fav") | H14: ='P&L Summary'!D13 | I14: ='P&L Summary'!Q13 | J14: =I14-H14 | K14: =IF(J14<0,"Unfav","Fav") | N14: ='P&L Summary'!E13 | O14: ='P&L Summary'!R13 | P14: =O14-N14 | Q14: =IF(P14<0,"Unfav","Fav") | T14: =T13/T7 | U14: =U13/U7 | V14: =U14-T14 | W14: =IF(V14<0,"Unfav","Fav")
A17: MANAGEMENT COMMENTARY — Q1 FY2025
A18: 2 paragraphs: (1) Revenue & Gross Profit drivers (2) OpEx & Operating Profit drivers. Name specific months and AED amounts.
A19: Paragraph 1 — Revenue & Gross Profit: Revenue came in at AED 1.90M against a January budget of AED 1.98M, a shortfall of AED 78K (-3.9%). Performance recovered through the quarter — February missed by AED 24K (-1.2%) and March delivered a small beat of AED 20K (+0.9%), supported by Ramadan uplift. COGS came in AED 29K below budget in January as lower volumes reduced input costs, but gross profit still missed by AED 49K as the revenue shortfall was not fully offset.
A20: Paragraph 2 — OpEx & EBITDA: EBITDA fell short by AED 91K (-10.1%) for the quarter, driven by two factors: a cumulative gross profit miss of AED 229K and an OpEx overspend of AED 70K (+3.4%). Marketing costs ran above plan in all three months, with March showing the largest deviation at AED 43K above budget. The combined effect compressed EBITDA margin by approximately 4.5 percentage points versus budget.

Sheet Rolling Forecast
A1: ZARA & CO. — ROLLING FORECAST FY2025
A2: Q1 actuals locked (Jan-Mar hardcoded). Apr-Dec = link from Revenue Build / COGS Build / OpEx Detail. FY Total = SUM of all 12 months. GP, EBITDA, margins = derived formulas.
A3: Colour key: | B3: Actual — locked | C3: Forecast (formula) | E3: FY Total
A5: Line Item | B5: Jan Actual | C5: Feb Actual | D5: Mar Actual | E5: Apr Fcst | F5: May Fcst | G5: Jun Fcst | H5: Jul Fcst | I5: Aug Fcst | J5: Sep Fcst | K5: Oct Fcst | L5: Nov Fcst | M5: Dec Fcst | N5: FY2025 Total
E6: Apr-Dec: link from Revenue Build row 39 / COGS Build row 26 / OpEx Detail row 23 | Col N: =SUM(B7:M7) for each row
A7: Revenue | B7: 1900000 | C7: 1860000 | D7: 2280000 | E7: ='Revenue Build'!F39 | F7: ='Revenue Build'!G39 | G7: ='Revenue Build'!H39 | H7: ='Revenue Build'!I39 | I7: ='Revenue Build'!J39 | J7: ='Revenue Build'!K39 | K7: ='Revenue Build'!L39 | L7: ='Revenue Build'!M39 | M7: ='Revenue Build'!N39 | N7: =SUM(B7:M7)
A8: Less: COGS | B8: 858000 | C8: 840000 | D8: 1040000 | E8: ='COGS Build'!F26 | F8: ='COGS Build'!G26 | G8: ='COGS Build'!H26 | H8: ='COGS Build'!I26 | I8: ='COGS Build'!J26 | J8: ='COGS Build'!K26 | K8: ='COGS Build'!L26 | L8: ='COGS Build'!M26 | M8: ='COGS Build'!N26 | N8: =SUM(B8:M8)
A9: Gross Profit | B9: =B7-B8 | C9: =C7-C8 | D9: =D7-D8 | E9: =E7-E8 | F9: =F7-F8 | G9: =G7-G8 | H9: =H7-H8 | I9: =I7-I8 | ... M9: =M7-M8 | N9: =SUM(B9:M9)
A10: Gross Margin % | B10: =B9/B7 | C10: =C9/C7 | D10: =D9/D7 | E10: =E9/E7 | F10: =F9/F7 | G10: =G9/G7 | H10: =H9/H7 | I10: =I9/I7 | ... N10: =N9/N7
A12: Less: OpEx | B12: 685000 | C12: 658000 | D12: 710000 | E12: ='OpEx Detail'!F23 | F12: ='OpEx Detail'!G23 | G12: ='OpEx Detail'!H23 | H12: ='OpEx Detail'!I23 | I12: ='OpEx Detail'!J23 | J12: ='OpEx Detail'!K23 | K12: ='OpEx Detail'!L23 | L12: ='OpEx Detail'!M23 | M12: ='OpEx Detail'!N23 | N12: =SUM(B12:M12)
A13: Operating Profit | B13: =B9-B12 | C13: =C9-C12 | D13: =D9-D12 | E13: =E9-E12 | F13: =F9-F12 | G13: =G9-G12 | H13: =H9-H12 | I13: =I9-I12 | ... M13: =M9-M12 | N13: =SUM(B13:M13)
A14: Operating Margin % | B14: =B13/B7 | C14: =C13/C7 | D14: =D13/D7 | E14: =E13/E7 | F14: =F13/F7 | G14: =G13/G7 | H14: =H13/H7 | I14: =I13/I7 | ... N14: =N13/N7

Sheet Scenario Analysis
A1: ZARA & CO. — SCENARIO ANALYSIS FY2025
A2: Base = budget assumptions linked from model. Bull = optimistic inputs. Bear = conservative inputs. P&L output in Section 2 recalculates automatically when you change Section 1 inputs.
A4: SECTION 1 — ASSUMPTIONS
A5: Assumption | B5: Base Case | C5: Bull Case | D5: Bear Case
A6: Full-Year Revenue (AED) | B6: ='P&L Summary'!O6 | C6: =$B$6+($B$6*C7) | D6: =$B$6+($B$6*D7) | F6: Link from P&L Summary col O, row 6
A7: Revenue Growth % vs Budget | B7: 0 | C7: 0.05 | D7: -0.05 | F7: Base = 0%. Bull/Bear: type the growth adjustment.
A8: Blended COGS % of Revenue | B8: ='P&L Summary'!O7/'P&L Summary'!O6 | C8: 0.42 | D8: 0.47 | F8: Base: derive from model. Bull = lower %, Bear = higher %.
A9: Full-Year OpEx (AED) | B9: ='P&L Summary'!O11 | C9: =$B$9+($B$9*C10) | D9: =$B$9+($B$9*D10) | F9: Link from P&L Summary col O, row 11
A10: OpEx Growth % vs Budget | B10: 0 | C10: -0.02 | D10: 0.05 | F10: Base = 0%. Bull = cost savings. Bear = overspend.
A12: SECTION 2 — P&L OUTPUT (formula-driven from Section 1)
A13: Line Item | B13: Base Case | C13: Bull Case | D13: Bear Case | F13: Bull vs Base ($) | G13: Bear vs Base ($)
A14: Revenue | B14: =B6 | C14: =C6 | D14: =D6 | F14: =C14-B14 | G14: =D14-B14
A15: Less: COGS | B15: =B14*B8 | C15: =C14*C8 | D15: =D14*D8 | F15: =C15-B15 | G15: =D15-B15
A16: Gross Profit | B16: =B14-B15 | C16: =C14-C15 | D16: =D14-D15 | F16: =C16-B16 | G16: =D16-B16
A17: Gross Margin % | B17: =B16/B14 | C17: =C16/C14 | D17: =D16/D14
A19: Less: OpEx | B19: =B9 | C19: =C9 | D19: =D9 | F19: =C19-B19 | G19: =D19-B19
A20: Operating Profit | B20: =B16-B19 | C20: =C16-C19 | D20: =D16-D19 | F20: =C20-B20 | G20: =D20-B20
A21: Operating Margin % | B21: =B20/B14 | C21: =C20/C14 | D21: =D20/D14

Sheet Dashboard
A1: ZARA & CO. — EXECUTIVE DASHBOARD FY2025
A2: All cells are formulas — links from P&L Summary (budget), Variance Analysis (Q1 actuals), Rolling Forecast (FY).
A4: SECTION 1 — Q1 KEY METRICS
B5: Q1 Revenue — Actual | C5: Q1 Operating Profit — Actual | D5: Q1 Operating Margin % | E5: Q1 EBITDA Margin %
B6: ='Variance Analysis'!U7 | C6: ='Variance Analysis'!U13 | D6: ='Variance Analysis'!U10 | E6: ='Variance Analysis'!U14
B7: Source: ='Variance Analysis'!U7 | C7: Source: ='Variance Analysis'!U13 | D7: Source: ='Variance Analysis'!U13/'Variance Analysis'!U7 | E7: Source: ='Variance Analysis'!U14
A9: SECTION 2 — Q1 SCORECARD (Actual vs Budget)
A10: Line Item | B10: Q1 Budget | C10: Q1 Actual | D10: $ Variance | E10: Fav/Unfav | F10: % Variance
A11: Revenue | B11: ='Variance Analysis'!T7 | C11: ='Variance Analysis'!U7 | D11: ='Variance Analysis'!V7 | E11: ='Variance Analysis'!W7 | F11: ='Variance Analysis'!X7
A12: Less: COGS | B12: ='Variance Analysis'!T8 | C12: ='Variance Analysis'!U8 | D12: ='Variance Analysis'!V8 | E12: ='Variance Analysis'!W8 | F12: ='Variance Analysis'!X8
A13: Gross Profit | B13: ='Variance Analysis'!T9 | C13: ='Variance Analysis'!U9 | D13: ='Variance Analysis'!V9 | E13: ='Variance Analysis'!W9 | F13: ='Variance Analysis'!X9
A14: Gross Margin % | B14: ='Variance Analysis'!T10 | C14: ='Variance Analysis'!U10 | D14: ='Variance Analysis'!V10 | E14: ='Variance Analysis'!W10 | F14: ='Variance Analysis'!X10
A16: Less: OpEx | B16: ='Variance Analysis'!T12 | C16: ='Variance Analysis'!U12 | D16: ='Variance Analysis'!V12 | E16: ='Variance Analysis'!W12 | F16: ='Variance Analysis'!X12
A17: Operating Profit | B17: ='Variance Analysis'!T13 | C17: ='Variance Analysis'!U13 | D17: ='Variance Analysis'!V13 | E17: ='Variance Analysis'!W13 | F17: ='Variance Analysis'!X13
A18: Operating Margin % | B18: ='Variance Analysis'!T14 | C18: ='Variance Analysis'!U14 | D18: ='Variance Analysis'!V14 | E18: ='Variance Analysis'!W14 | F18: ='Variance Analysis'!X14
A20: SECTION 3 — FULL YEAR OUTLOOK (Budget vs Rolling Forecast)
A21: Line Item | B21: FY2025 Budget | C21: Rolling Forecast | D21: $ Variance | E21: Fav/Unfav | F21: % Variance
A22: Revenue | B22: ='P&L Summary'!O6 | C22: ='Rolling Forecast'!N7 | D22: =C22-B22 | E22: =IF(D22<0,"Unfav","Fav") | F22: =D22/B22
A23: Less: COGS | B23: ='P&L Summary'!O7 | C23: ='Rolling Forecast'!N8 | D23: =C23-B23 | E23: =IF(D23>0,"Unfav","Fav") | F23: =D23/B23
A24: Gross Profit | B24: ='P&L Summary'!O8 | C24: ='Rolling Forecast'!N9 | D24: =C24-B24 | E24: =IF(D24<0,"Unfav","Fav") | F24: =D24/B24
A25: Gross Margin % | B25: ='P&L Summary'!O9 | C25: ='Rolling Forecast'!N10 | D25: =C25-B25 | E25: =IF(D25<0,"Unfav","Fav") | F25: =D25/B25
A27: Less: OpEx | B27: ='P&L Summary'!O11 | C27: ='Rolling Forecast'!N12 | D27: =C27-B27 | E27: =IF(D27>0,"Unfav","Fav") | F27: =D27/B27
A28: Operating Profit | B28: ='P&L Summary'!O12 | C28: ='Rolling Forecast'!N13 | D28: =C28-B28 | E28: =IF(D28<0,"Unfav","Fav") | F28: =D28/B28
A29: Operating Margin % | B29: ='P&L Summary'!O13 | C29: ='Rolling Forecast'!N14 | D29: =C29-B29 | E29: =IF(D29<0,"Unfav","Fav") | F29: =D29/B29
